---
title: 2021-05-31-异常
tags: Java异常
category: 2021-05
renderNumberedHeading: true
grammar_cjkRuby: true
---
# 异常

异常是程序经常会出现的，发现错误的最佳时机是在编译阶段，也就是你试图在运行程序之前。但是，在编译期间并不能找到所有的错误，有一些NullPointerException和ClassNotFoundException 异常在编译期找不到，这些异常是RuntimeException运行时异常，这些异常往往在运行时才能被发现。
我们写Java 程序经常会出现两种问题，一种是java.lang.Exception，一种是java.lang.Error，都用来表示出现了异常情况。

## **认识Exception**

Exception 位于java.lang 包下，是一种顶级接口，继承于 Throwable 类，Exception 类及其子类都是 Throwable 的组成条件，是程序出现的合理情况。

## **什么是 Throwable**

Throwable 类是 Java 语言中所有错误（erros）和异常（exceptions）的父类。只有继承于Throwable 的类或者其子类才能够被抛出，还有一种方式是带有Java 中的 @throw 的注解类也可以抛出 。

在 Java中，除了 RuntimeException 和其子类，以及 error 和其子类，其他所有的异常都是 checkedExceptio 。

Throwable 及其子类进行归类分析

![enter description here](https://cdn.jsdelivr.net/gh/jiasuo001/jiasuo-image@main/image/异常.5lzacbztd880.png)

## 常见的  Exception

**RuntimeException**

![enter description here](https://cdn.jsdelivr.net/gh/jiasuo001/jiasuo-image@main/image/RuntimeException异常.hkjr5yo3g08.png)

**UncheckedException**

![enter description here](https://cdn.jsdelivr.net/gh/jiasuo001/jiasuo-image@main/image/UncheckedException异常.71hratjio6c0.png)



| **异常类型**                   | **说**  **明**                       |
| ------------------------------ | ------------------------------------ |
| Exception                      | 异常层次结构的根类                   |
| ArithmeticException            | 算术错误情形，如以零作除数           |
| ArrayIndexOutOfBoundsException | 数组下标越界                         |
| NullPointerException           | 尝试访问 null 对象成员               |
| ClassNotFoundException         | 不能加载所需的类                     |
| InputMismatchException         | 欲得到数据类型与实际输入类型不匹配   |
| IllegalArgumentException       | 方法接收到非法参数                   |
| ClassCastException             | 对象强制类型转换出错                 |
| NumberFormatException          | 数字格式转换异常，如把"ab"转换成数字 |

##  与 Exception 有关的 Java 关键字

**关键字：try、catch、 finally、throw、throws**

**异常处理**

![enter description here](https://cdn.jsdelivr.net/gh/jiasuo001/jiasuo-image@main/image/异常处理.5swhzlh8j6k0.png)



#### 【示例1】引入异常

```java
public class TestException1 {
    public static void main(String[] args) {
        Scanner input = new Scanner(System.in);
        //输入总分
        System.out.println("请输入总分");
        int sum = input.nextInt();
        //输入人数
        System.out.println("请输入人数");
        int count = input.nextInt();
        //求平均分并输出
        int result = sum / count;
        System.out.println("result="+result);
        System.out.println("3q3q");
System.out.println("bye");
    }
}
```

情况1：总分和人数都正确输入，输出结果，并3q3q。

![enter description here](https://cdn.jsdelivr.net/gh/jiasuo001/jiasuo-image@main/image/运行结果1.4aeo5xi52x8.png)

情况2：人数为零，后面结果和3q3q不再输出

![enter description here](https://cdn.jsdelivr.net/gh/jiasuo001/jiasuo-image@main/image/运行结果2.2p5k0empboy0.png)

 

情况3：输入非数字，后面结果和3q3q不再输出

![enter description here](https://cdn.jsdelivr.net/gh/jiasuo001/jiasuo-image@main/image/运行结果3.6rxj0j9b4f00.png)

优点：Java已经提供了异常处理机制，发生异常后，会给出异常类型、异常提示信息、异常的位置

缺点：出现异常后，后续语句不执行了；提示信息太专业，可读性差

**解决：try-catch-finally 处理异常；throws 抛出异常不处理，调用者处理**





### 异常处理：try-catch-finally

#### 【示例2】使用try-catch处理异常

```java
public class TestException2 {
    public static void main(String[] args) {
        Scanner input = new Scanner(System.in);
        try{
            //输入总分
            System.out.println("请输入总分");
            int sum = input.nextInt(); 
            //输入人数
            System.out.println("请输入人数");
            int count = input.nextInt();
            //求平均分并输出
            int result = sum / count;
            System.out.println("result="+result);
            return; // 方法结束，后面的语句不会执行
        }catch(Exception e){
            //输出异常的底层信息
            //e.printStackTrace();          
//System.out.println(e.toString());
//System.out.println(e.getMessage());/// by zero
        //输出用户自定义异常信息
        System.err.println("请检查人数是否为0，请检查是否输入了非数字内容");
        //继续向上抛出异常 （catch后面的语句就不执行了）
        //throw  e;
    }
        System.out.println("3q3q");
System.out.println("bye");
}
}
```

**try-catch****执行情况**

​	情况1：try块中代码没有出现异常

​				 不执行catch块代码，执行catch块后边的代码

​	情况2：try块中代码出现异常，catch中异常类型匹配（相同或者父类）

​				 执行catch块代码，执行catch块后边的代码

​	情况3：try块中代码出现异常， catch中异常类型不匹配

​				 不执行catch块代码，不执行catch块后边的代码，程序会中断运行

注意：

1. 出现异常后，Java会生成相应的异常对象，Java系统,寻找匹配的catch块，找到后将异常对象付给catch块异常参数；
2. 出现异常后，try块中尚未执行的语句不会执行；
3. 出现异常后并处理后，catch块后面的语句还会执行。



**catch 中如何处理异常**

​	输出用户自定义异常信息

​	System.err.println("除数不能为零。");

​	System.err.println("被除数和除数必须是整数。");



​	调用异常对象的方法输出异常信息

​	toString ( )方法，显示异常的类名和产生异常的原因

​	void printStackTrace()  输出异常的堆栈信息

​	String getMessage()返回异常信息描述字符串，printStackTrace()信息一部分



​	继续向上抛出异常

​	throw e



问题1：在什么情况下，catch后面的语句是不执行的

​    情况1：throw e;

​    情况2：发生的异常和catch中异常类型不匹配

​    情况3：return 

 问题2：不管什么情况下，希望某些语句都执行，怎么办

   finally语句



#### 【示例3】使用try-catch-finally处理异常

```java
public class TestException3 {
    public static void main(String[] args) {
        Scanner input = new Scanner(System.in);
        try{
            //输入总分
            System.out.println("请输入总分");
            int sum = input.nextInt(); 
            //输入人数
            System.out.println("请输入人数");
            int count = input.nextInt();
            //求平均分并输出
            int result = sum / count;
            System.out.println("result="+result);
            System.exit(0);//结束虚拟机的运行
            //return; // 方法结束，后面的语句不会执行
        }catch(Exception e){
            //输出用户自定义异常信息
            System.err.println("请检查人数是否为0，请检查是否输入了非数字内容");
            //继续向上抛出异常 （catch后面的语句就不执行了）
            throw  e;
        }finally{
            System.out.println("3q3q");
        }
        System.out.println("bye");
    }
}
```

问题3：return和finally语句的执行顺序

   执行return之前的语句----执行finally语句-----执行return

 

问题4：finally在实际开发中的使用场合

   IO流的管理，数据库连接的关闭  socket的关闭

 

问题5：唯一的例外

   System.exit(0); 终止当前正在运行的 Java 虚拟机。

 

 

**问题：一段代码可能会引发多种类型的异常，是否可以分开处理**



#### 【示例4】使用多重catch处理异常

```java
public class TestException4 {
    public static void main(String[] args) {
        Scanner input = new Scanner(System.in);
        try{
            //输入总分
            System.out.println("请输入总分");
            int sum = input.nextInt(); 
            //输入人数
            System.out.println("请输入人数");
            int count = input.nextInt();
            //求平均分并输出
            int result = sum / count;
            System.out.println("result="+result);
        }catch(InputMismatchException  e){ 
            System.err.println("请检查是否输入了非数字内容");
        }catch(ArithmeticException e){
            System.err.println("请检查人数是否为0");
        }catch(Exception e){
            //输出异常的底层信息
            System.err.println("other exception:"+e.toString());
        }
        finally{
            System.out.println("3q3q");
        }
        System.out.println("bye");
    }
}
```

​	当引发异常时，会按顺序来查看每个 catch 语句，并执行第一个与异常类型匹配的catch语句

​	执行其中一条 catch 语句后，其后 catch 语句将被忽略 

​	在安排catch语句的顺序时，首先应该捕获最特殊的异常， 然后再逐渐一般化，即先子类后父类 

​	JDK7异常新处理方式：catch(InputMismatchException | ArithmeticException e){}



#### 【示例5】区分运行时异常和检查异常

```java
public class TestException5 {
    public static void main(String[] args) {
        //运行时异常，异常可以不进行捕获，运行时才会发生异常
        String str= "bjsxt";
        System.out.println(str.toUpperCase());
        NullPointerException ne;
        ArithmeticException ae;
        InputMismatchException ime;
        ClassCastException cce;
        int result = 10 / 0 ;
        //检查异常 checked  Exception
        try {
            Class.forName("com.bjsxt.adfadfa.afasdfad").newInstance();
        } catch (ClassNotFoundException e) {
            e.printStackTrace();
        } catch (IllegalAccessException e) {
            e.printStackTrace();
        } catch (InstantiationException e) {
            e.printStackTrace();
        }
        try {
            InputStream is = new FileInputStream("d:/bjsxt.txt");
        } catch (FileNotFoundException e) {
            e.printStackTrace();
        }
    }
}
```



### 异常处理：throws、throw

**手动抛出异常throw**

​	Java异常类对象除在程序执行过程中出现异常时由系统自动生成并抛出，也可根据需要手工创建并抛出。

​	在捕获一个异常前，必须有一段代码先生成异常对象并把它抛出。这个过程我们可以手工做，也可以由JRE来实	现，但是他们调用的都是throw子句。

**注意抛出运行时异常和Checked异常的区别**

​	抛出Checked异常，该throw语句要么处于try块中，要么方法签名中是有throws抛出

​	抛出运行时异常，没有以上要求

 

**声明异常throws**

​	当Checked Exception产生时，不一定立刻处理它，可以再把异常Throws出去

​	如果一个方法抛出多个已检查异常，就必须在方法的首部列出所有的异常，之间以逗号隔开

**子类声明的异常范围不能超过父类声明范围：**父类没有声明异常，子类也不能；不可抛出原有方法抛出异常类的父	类或上层类



#### 【示例6】throw和throws的使用1：除数不能是负数

```java
public class TestException6 {
    public static void main(String[] args) throws Exception {
        try {
            getAvg();
        } catch (Exception e) {
            e.printStackTrace();
        }
        getAvg();
    }
    public static void getAvg() throws Exception {
        try{
            Scanner input = new Scanner(System.in);
            //输入总分
            System.out.println("请输入总分");
            int sum = input.nextInt();

            //输入人数
            System.out.println("请输入人数");
            int count = input.nextInt();
            if(count<0){
               //throw  new RuntimeException("人数不能是负数："+count);
               throw  new Exception("人数不能是负数："+count);
            }
            //求平均分并输出
            int result = sum / count;

            System.out.println("result="+result);
        }catch (ArithmeticException e){
            e.printStackTrace();
        }catch (InputMismatchException e){
            e.printStackTrace();
        }catch (Exception e){
            //先处理
            e.printStackTrace();
            //再抛出
            throw e;
        }finally{
            System.out.println("3q3q");
        }

        System.out.println("bye");
    }
}
```

#### 【示例7】throw和throws的使用：限制年龄范围

```java
public class Person {
    private String name;
    private int age;
    public Person() {
    }
    public Person(String name, int age) {
        this.name = name;
        this.age = age;
    }
    public String getName() {
        return name;
    }
    public void setName(String name) {
        this.name = name;
    }
    public int getAge() {
        return age;
    }
    public void setAge(int age) throws Exception {
        if(age<1 || age>120){
            //System.out.println("年龄错误，必须在1-120岁之间");
            //throw new RuntimeException("年龄错误，必须在1-120岁之间:"+age);
            throw new Exception("年龄错误，必须在1-120岁之间:"+age);
        }else{
            this.age = age;
        }
    }
    @Override
    public String toString() {
        return "Person{name='" + name + '\'' +", age=" + age + '}';
    }
    public static void main(String[] args) {
        Person person = new Person();
        person.setName("小明");
        try {
            person.setAge(340);
        } catch (Exception e) {
            e.printStackTrace();
        }
        System.out.println(person);
    }
}
```



### 自定义异常

在程序中，可能会遇到任何标准异常类都没有充分的描述清楚的问题，这种情况下可以创建自己的异常类。

从Exception类或者它的子类派生一个子类即可。习惯上，定义的类应该包含2个构造器：一个是默认构造器，另一个是带有详细信息的构造器

#### 【示例8】自定义异常

```java
public class AgeException extends RuntimeException {
    public AgeException() {
    }
    public AgeException(String message) {
        super(message);
    }
}

public class CountMinusException extends Exception {
    public CountMinusException() {
        super();
    }
    public CountMinusException(String message) {
        super(message);
    }
}

//throw new CountMinusException("人数不能是负数："+count);
//throw new AgeException("年龄错误，必须在1-120岁之间:"+age);
```



## 什么是 Error

Error 是程序无法处理的错误，表示运行应用程序中较严重问题。大多数错误与代码编写者执行的操作无关，而表示代码运行时JVM（Java虚拟机）出现的问题。这些错误是不可检查的，因为它们在应用程序的控制和处理能力之外，而且绝大多数是程序运行时不允许出现的状况，比如0utOfMemoryError 和StackOverfLowError异常的出现。